<?xml version="1.0"?>
<robot xmlns:sensor="http://playerstage.sourceforge.net/gazebo/xmlschema/#sensor"
       xmlns:controller="http://playerstage.sourceforge.net/gazebo/xmlschema/#controller"
       xmlns:interface="http://playerstage.sourceforge.net/gazebo/xmlschema/#interface">

  <include filename="$(find kuka_lwr_description)/defs/util_defs.xml"/>

  <property name="arm_elem_base_mass" value="2.0"/>
  <property name="arm_elem_link_mass" value="2.0"/>
  <property name="arm_elem_ball_link_mass" value="2.0"/>
  <property name="arm_elem_end_link_mass" value="2.0"/>  
  <property name="arm_elem_flange_link_mass" value="0.5"/>
  <property name="safety_controller_k_pos" value="100" />
  <property name="safety_controller_k_vel" value="2" />
  <property name="joint_damping" value="0.1" />
  <property name="joint_damping_nico" value="0.03" />

  <property name="arm_velocity_scale_factor" value="1"/>

  <macro name="kuka_lwr_arm" params="parent name *origin">

    <joint name="${parent}_${name}_arm_base_joint" type="fixed">
      <insert_block name="origin"/>
      <parent link="${parent}"/>
      <child link="calib_${name}_arm_base_link"/>
    </joint>

    <link name="calib_${name}_arm_base_link">
      <inertial>
        <mass value="${arm_elem_base_mass}"/>
        <origin xyz="0 0 0.055" rpy="0 0 0"/>
        <cylinder_inertia_def radius="0.06" length="0.11"
                              mass="${arm_elem_base_mass}"/>
      </inertial>

      <visual>
        <origin xyz="0 0 0" rpy="0 0 0"/>
        <geometry>
          <mesh filename="package://kuka_lwr_description/meshes/arm_base.stl"/>
        </geometry>
        <material name="Orange"/>
      </visual>
      <collision>
        <origin xyz="0 0 0" rpy="0 0 0"/>
        <geometry>
          <mesh filename="package://kuka_lwr_description/meshes/convex/arm_base_convex.stl"/>
        </geometry>
      </collision>
    </link>

    <gazebo reference="calib_${name}_arm_base_link">
      <material value="Gazebo/Orange"/>
    </gazebo>

    <joint name="${name}_arm_0_joint" type="revolute">
      <origin xyz="0 0 0.11" rpy="0 0 0"/>
      <axis xyz="0 0 1"/>
      <limit lower="${-170 * M_PI / 180}" upper="${170 * M_PI / 180}"
             effort="204" velocity="${arm_velocity_scale_factor * 110 * M_PI / 180}" />
      <!--safety_controller soft_lower_limit="${-168 * M_PI / 180}"
                         soft_upper_limit="${168 * M_PI / 180}"
                         k_position="${safety_controller_k_pos}"
                         k_velocity="${safety_controller_k_vel}"/-->
      <dynamics damping="${joint_damping}"/>
      <parent link="calib_${name}_arm_base_link"/>
      <child link="${name}_arm_1_link"/>
    </joint>




    <link name="${name}_arm_1_link">
      <inertial>
        <mass value="${arm_elem_link_mass}"/>
        <origin rpy="0 0 0" xyz="0 0.05 0.130"/>
        <cuboid_inertia_def length="0.26" width="0.06" height="0.12"
                            mass="${arm_elem_link_mass}"/>
      </inertial>

      <visual>
        <origin xyz="0 0 0" rpy="0 0 ${M_PI}"/>
        <geometry>
          <mesh filename="package://kuka_lwr_description/meshes/arm_segment_a.stl"/>
        </geometry>
        <material name="Orange"/>
      </visual>

      <collision>
        <origin xyz="0 0 0" rpy="0 0 ${M_PI}"/>
        <geometry>
          <mesh filename="package://kuka_lwr_description/meshes/convex/arm_segment_a_convex.stl"/>
        </geometry>
      </collision>
    </link>

    <gazebo reference="${name}_arm_1_link">
      	<material value="Gazebo/Orange"/>
    	<mu1>0.2</mu1>
    	<mu2>0.2</mu2>
        <dampingFactor>${joint_damping_nico}</dampingFactor>
    </gazebo>
    <gazebo reference="${name}_arm_2_link">
      	<material value="Gazebo/Orange"/>
    	<mu1>0.2</mu1>
    	<mu2>0.2</mu2>
        <dampingFactor>${joint_damping_nico}</dampingFactor>
    </gazebo>
    <gazebo reference="${name}_arm_3_link">
      	<material value="Gazebo/Orange"/>
    	<mu1>0.2</mu1>
    	<mu2>0.2</mu2>
        <dampingFactor>${joint_damping_nico}</dampingFactor>
    </gazebo>
    <gazebo reference="${name}_arm_4_link">
      	<material value="Gazebo/Orange"/>
    	<mu1>0.2</mu1>
    	<mu2>0.2</mu2>
        <dampingFactor>${joint_damping_nico}</dampingFactor>
    </gazebo>
    <gazebo reference="${name}_arm_5_link">
      	<material value="Gazebo/Orange"/>
    	<mu1>0.2</mu1>
    	<mu2>0.2</mu2>
        <dampingFactor>${joint_damping_nico}</dampingFactor>
    </gazebo>
    <gazebo reference="${name}_arm_6_link">
      	<material value="Gazebo/Orange"/>
    	<mu1>0.2</mu1>
    	<mu2>0.2</mu2>
        <dampingFactor>${joint_damping_nico}</dampingFactor>
    </gazebo>
    <gazebo reference="${name}_arm_7_link">
      	<material value="Gazebo/Orange"/>
    	<mu1>0.2</mu1>
    	<mu2>0.2</mu2>
        <dampingFactor>${joint_damping_nico}</dampingFactor>
    </gazebo>

    <transmission name="${name}_arm_0_trans" type="pr2_mechanism_model/SimpleTransmission">
      <actuator name="${name}_arm_0_motor"/>
      <joint name="${name}_arm_0_joint"/>
      <mechanicalReduction>1.0</mechanicalReduction>
    </transmission>

  <!-- transmission name="${name}_arm_0_trans">
    <type>transmission_interface/SimpleTransmission</type>
    <joint name="${name}_arm_0_joint">
      <hardwareInterface>EffortJointInterface</hardwareInterface>
    </joint>
    <actuator name="${name}_arm_0_motor">
      <mechanicalReduction>1</mechanicalReduction>
    </actuator>
  </transmission -->


    <joint name="${name}_arm_1_joint" type="revolute">
      <origin xyz="0 0 0.20" rpy="0 0 0"/>
      <axis xyz="0 -1 0"/>
      <limit lower="${-90 * M_PI / 180}" upper="${90 * M_PI / 180}"
             effort="306" velocity="${arm_velocity_scale_factor * 110 * M_PI / 180}" />       
      <safety_controller soft_lower_limit="${-118 * M_PI / 180}"
                         soft_upper_limit="${118 * M_PI / 180}"
                         k_position="${safety_controller_k_pos}"
                         k_velocity="${safety_controller_k_vel}"/>
      <dynamics damping="${joint_damping}"/>
      <parent link="${name}_arm_1_link"/>
      <child link="${name}_arm_2_link"/>
    </joint>

    <link name="${name}_arm_2_link">
      <inertial>
        <mass value="${arm_elem_link_mass}"/>
        <origin rpy="0 0 0" xyz="0 -0.05 ${0.130 - 0.06}"/>
        <!--cuboid_inertia_def length="0.12" width="0.06" height="0.260"
                            mass="${arm_elem_link_mass}"/-->

        <cuboid_inertia_def length="0.26" width="0.06" height="0.12"
                            mass="${arm_elem_link_mass}"/>
      </inertial>

      <visual>
        <origin xyz="0 0 0.2" rpy="${M_PI} 0 ${M_PI}"/>
        <geometry>
          <mesh filename="package://kuka_lwr_description/meshes/arm_segment_b.stl"/>
        </geometry>
        <material name="Orange"/>
      </visual>

      <collision>
        <origin xyz="0 0 0.2" rpy="${M_PI} 0 ${M_PI}"/>
        <geometry>
          <mesh filename="package://kuka_lwr_description/meshes/convex/arm_segment_b_convex.stl"/>
        </geometry>
      </collision>
    </link>

    <gazebo reference="${name}_arm_2_link">
      <material value="Gazebo/Orange"/>
    </gazebo>

    <transmission name="${name}_arm_1_trans" type="pr2_mechanism_model/SimpleTransmission">
      <actuator name="${name}_arm_1_motor"/>
      <joint name="${name}_arm_1_joint"/>
      <mechanicalReduction>1.0</mechanicalReduction>
    </transmission>

    <!-- transmission name="${name}_arm_1_trans">
    <type>transmission_interface/SimpleTransmission</type>
      <actuator name="${name}_arm_1_motor"/>
      <joint name="${name}_arm_1_joint">
    <hardwareInterface>EffortJointInterface</hardwareInterface>
    </joint>
      <mechanicalReduction>1.0</mechanicalReduction>
    </transmission -->


    <joint name="${name}_arm_2_joint" type="revolute">
      <origin xyz="0 0 0.20" rpy="0 0 0"/>
      <axis xyz="0 0 1"/>
      <limit lower="${-170 * M_PI / 180}" upper="${170 * M_PI / 180}"
             effort="204" velocity="${arm_velocity_scale_factor * 130 * M_PI / 180}" />
      <!--safety_controller soft_lower_limit="${-168 * M_PI / 180}"
                         soft_upper_limit="${168 * M_PI / 180}"
                         k_position="${safety_controller_k_pos}"
                         k_velocity="${safety_controller_k_vel}"/-->
      <dynamics damping="${joint_damping}"/>
      <parent link="${name}_arm_2_link"/>
      <child link="${name}_arm_3_link"/>
    </joint>

    <link name="${name}_arm_3_link">
      <inertial>
        <mass value="${arm_elem_link_mass}"/>
        <origin rpy="0 0 0" xyz="0 -0.06 0.130"/>
        <cuboid_inertia_def length="0.26" width="0.06" height="0.12"
                            mass="${arm_elem_link_mass}"/>
      </inertial>

      <visual>
        <origin xyz="0 0 0" rpy="0 0 0"/>
        <geometry>
          <mesh filename="package://kuka_lwr_description/meshes/arm_segment_a.stl"/>
        </geometry>
        <material name="Orange"/>
      </visual>

      <collision>
        <origin xyz="0 0 0" rpy="0 0 0"/>
        <geometry>
          <mesh filename="package://kuka_lwr_description/meshes/convex/arm_segment_a_convex.stl"/>
        </geometry>
      </collision>
    </link>

    <gazebo reference="${name}_arm_3_link">
      <material value="Gazebo/Orange"/>
    </gazebo>

    <transmission name="${name}_arm_2_trans" type="pr2_mechanism_model/SimpleTransmission">
      <actuator name="${name}_arm_2_motor"/>
      <joint name="${name}_arm_2_joint"/>
      <mechanicalReduction>1.0</mechanicalReduction>
    </transmission>

    <!-- transmission name="${name}_arm_2_trans">
    <type>transmission_interface/SimpleTransmission</type>
      <actuator name="${name}_arm_2_motor"/>
      <joint name="${name}_arm_2_joint">
    <hardwareInterface>EffortJointInterface</hardwareInterface>
    </joint>
      <mechanicalReduction>1.0</mechanicalReduction>
    </transmission -->


    <joint name="${name}_arm_3_joint" type="revolute">
      <origin xyz="0 0 0.20" rpy="0 0 0"/>
      <axis xyz="0 1 0"/>
      <limit lower="${-120 * M_PI / 180}" upper="${120 * M_PI / 180}"
             effort="306" velocity="${arm_velocity_scale_factor * 130 * M_PI / 180}" />
      <safety_controller soft_lower_limit="${-118 * M_PI / 180}"
                         soft_upper_limit="${118 * M_PI / 180}"
                         k_position="${safety_controller_k_pos}"
                         k_velocity="${safety_controller_k_vel}"/>
      <dynamics damping="${joint_damping}"/>
      <parent link="${name}_arm_3_link"/>
      <child link="${name}_arm_4_link"/>
    </joint>

    <link name="${name}_arm_4_link">
      <inertial>
        <mass value="${arm_elem_link_mass}"/>
        <origin rpy="0 0 0" xyz="0 0.06 ${0.130 - 0.06}"/>
        <cuboid_inertia_def length="0.26" width="0.06" height="0.12"
                            mass="${arm_elem_link_mass}"/>
      </inertial>

      <visual>
        <origin xyz="0 0 0.2" rpy="0 ${M_PI} ${M_PI}"/>
        <geometry>
          <mesh filename="package://kuka_lwr_description/meshes/arm_segment_b.stl"/>
        </geometry>
        <material name="Orange"/>
      </visual>

      <collision>
        <origin xyz="0 0 0.2" rpy="0 ${M_PI} ${M_PI}"/>
        <geometry>
          <mesh filename="package://kuka_lwr_description/meshes/convex/arm_segment_b_convex.stl"/>
        </geometry>
      </collision>
    </link>

    <gazebo reference="${name}_arm_4_link">
      <material value="Gazebo/Orange"/>
    </gazebo>

    <transmission name="${name}_arm_3_trans" type="pr2_mechanism_model/SimpleTransmission">
      <actuator name="${name}_arm_3_motor"/>
      <joint name="${name}_arm_3_joint"/>
      <mechanicalReduction>1.0</mechanicalReduction>
    </transmission>

    <!-- transmission name="${name}_arm_3_trans">
    <type>transmission_interface/SimpleTransmission</type>
      <actuator name="${name}_arm_3_motor"/>
      <joint name="${name}_arm_3_joint">
    <hardwareInterface>EffortJointInterface</hardwareInterface>
    </joint>
      <mechanicalReduction>1.0</mechanicalReduction>
    </transmission -->

    <joint name="${name}_arm_4_joint" type="revolute">
      <origin xyz="0 0 0.20" rpy="0 0 0"/>
      <axis xyz="0 0 1"/>
      <limit lower="${-170 * M_PI / 180}" upper="${170 * M_PI / 180}"
             effort="204" velocity="${arm_velocity_scale_factor * 130 * M_PI / 180}" />
      <safety_controller soft_lower_limit="${-168 * M_PI / 180}"
                         soft_upper_limit="${168 * M_PI / 180}"
                         k_position="${safety_controller_k_pos}"
                         k_velocity="${safety_controller_k_vel}"/>
      <dynamics damping="${joint_damping}"/>
      <parent link="${name}_arm_4_link"/>
      <child link="${name}_arm_5_link"/>
    </joint>

    <link name="${name}_arm_5_link">
      <inertial>
        <mass value="${arm_elem_link_mass}"/>
        <origin rpy="0 0 0" xyz="0 0 0.124"/>
        <cuboid_inertia_def length="0.248" width="0.06" height="0.12"
                            mass="${arm_elem_link_mass}"/>
      </inertial>

      <visual>
        <origin xyz="0 0 0" rpy="0 0 ${M_PI}"/>
        <geometry name="${name}_arm_5_geom">
          <mesh filename="package://kuka_lwr_description/meshes/arm_segment_last.stl"/>
        </geometry>
        <material name="Orange"/>
      </visual>

      <collision>
        <origin xyz="0 0 0" rpy="0 0 ${M_PI}"/>
        <geometry>
          <mesh filename="package://kuka_lwr_description/meshes/convex/arm_segment_last_convex.stl"/>
        </geometry>
      </collision>
    </link>

    <gazebo reference="${name}_arm_5_link">
      <material value="Gazebo/Orange"/>
    </gazebo>

    <transmission name="${name}_arm_4_trans" type="pr2_mechanism_model/SimpleTransmission">
      <actuator name="${name}_arm_4_motor"/>
      <joint name="${name}_arm_4_joint"/>
      <mechanicalReduction>1.0</mechanicalReduction>
    </transmission>

    <!-- transmission name="${name}_arm_4_trans">
    <type>transmission_interface/SimpleTransmission</type>
      <actuator name="${name}_arm_4_motor"/>
      <joint name="${name}_arm_4_joint">
    <hardwareInterface>EffortJointInterface</hardwareInterface>
    </joint>
      <mechanicalReduction>1.0</mechanicalReduction>
    </transmission -->



    <joint name="${name}_arm_5_joint" type="revolute">
      <origin xyz="0 0 0.19" rpy="0 0 0"/>
      <axis xyz="0 -1 0"/>
      <limit lower="${-120 * M_PI / 180}" upper="${120 * M_PI / 180}"
             effort="306" velocity="${arm_velocity_scale_factor * 180 * M_PI / 180}" />
      <safety_controller soft_lower_limit="${-118 * M_PI / 180}"
                         soft_upper_limit="${118 * M_PI / 180}"
                         k_position="${safety_controller_k_pos}"
                         k_velocity="${safety_controller_k_vel}"/>
      <dynamics damping="${joint_damping}"/>
      <parent link="${name}_arm_5_link"/>
      <child link="${name}_arm_6_link"/>
    </joint>

    <link name="${name}_arm_6_link">
      <inertial>
        <mass value="${arm_elem_ball_link_mass}"/>
        <origin rpy="0 0 0" xyz="0 0 0.0625"/>
        <cuboid_inertia_def length="0.125" width="0.125" height="0.125"
                            mass="${arm_elem_ball_link_mass}"/>
      </inertial>

      <visual>
        <origin xyz="0 0 0" rpy="0 0 ${M_PI}"/>
        <geometry>
          <mesh filename="package://kuka_lwr_description/meshes/arm_wrist.stl"/>
        </geometry>
        <material name="Grey"/>
      </visual>

      <collision>
        <origin xyz="0 0 0" rpy="0 0 ${M_PI}"/>
        <geometry>
          <mesh filename="package://kuka_lwr_description/meshes/convex/arm_wrist_convex.stl"/>
        </geometry>
      </collision>
    </link>

    <gazebo reference="${name}_arm_6_link">
      <material value="Gazebo/Orange"/>
    </gazebo>

    <transmission name="${name}_arm_5_trans" type="pr2_mechanism_model/SimpleTransmission">
      <actuator name="${name}_arm_5_motor"/>
      <joint name="${name}_arm_5_joint"/>
      <mechanicalReduction>1.0</mechanicalReduction>
    </transmission>

    <!-- transmission name="${name}_arm_5_trans">
    <type>transmission_interface/SimpleTransmission</type>
      <actuator name="${name}_arm_5_motor"/>
      <joint name="${name}_arm_5_joint">
    <hardwareInterface>EffortJointInterface</hardwareInterface>
    </joint>
      <mechanicalReduction>1.0</mechanicalReduction>
    </transmission -->


    <joint name="${name}_arm_6_joint" type="revolute">
      <origin xyz="0 0 0.078" rpy="0 0 0"/>
      <axis xyz="0 0 1"/>
      <limit lower="${-170 * M_PI / 180}" upper="${170 * M_PI / 180}"
             effort="204" velocity="${arm_velocity_scale_factor * 180 * M_PI / 180}" />
      <safety_controller soft_lower_limit="${-168 * M_PI / 180}"
                         soft_upper_limit="${168 * M_PI / 180}"
                         k_position="${safety_controller_k_pos}"
                         k_velocity="${safety_controller_k_vel}"/>
      <dynamics damping="${joint_damping}"/>
      <parent link="${name}_arm_6_link"/>
      <child link="${name}_arm_7_link"/>
    </joint>

    <link name="${name}_arm_7_link">
      <inertial>
        <mass value="${arm_elem_end_link_mass}"/>
        <origin xyz="0 0 0"/>
        <cuboid_inertia_def length="0.2" width="0.2" height="0.2"
                            mass="${arm_elem_end_link_mass}"/>
      </inertial>
      <visual>
        <origin xyz="0 0 0" rpy="0 0 ${-1/4 * M_PI  +  M_PI}"/>
        <geometry>
          <mesh filename="package://kuka_lwr_description/meshes/arm_flanche.stl"/>
        </geometry>
        <material name="Grey"/>
      </visual>
      <collision>
        <origin xyz="0 0 0" rpy="0 0 ${ -1/4 * M_PI  +  M_PI}"/>
        <geometry>
          <mesh filename="package://kuka_lwr_description/meshes/convex/arm_flanche_convex.stl"/>
        </geometry>
      </collision>
    </link>

    <gazebo reference="${name}_arm_7_link">
      <material value="Gazebo/Grey"/>
    </gazebo>

    <transmission name="${name}_arm_6_trans" type="pr2_mechanism_model/SimpleTransmission">
      <actuator name="${name}_arm_6_motor"/>
      <joint name="${name}_arm_6_joint"/>
      <mechanicalReduction>1.0</mechanicalReduction>
    </transmission>

    <!-- transmission name="${name}_arm_6_trans">
    <type>transmission_interface/SimpleTransmission</type>
      <actuator name="${name}_arm_6_motor"/>
      <joint name="${name}_arm_6_joint">
    <hardwareInterface>EffortJointInterface</hardwareInterface>
    </joint>
      <mechanicalReduction>1.0</mechanicalReduction>
    </transmission -->

    
   <joint name="${name}_arm_flange_joint" type="fixed">
      <origin xyz="0 0 0" rpy="0 0 0"/>
      <parent link="${name}_arm_7_link"/>
      <child link="${name}_arm_flange_link"/>
   </joint>

   <link name="${name}_arm_flange_link">
      <inertial>
        <mass value="${arm_elem_flange_link_mass}"/>
        <origin xyz="0 0 0" rpy="0 0 0"/>
        <cuboid_inertia_def length="1" width="1" height="1"
                            mass="${arm_elem_flange_link_mass}"/>
      </inertial>

   </link>

    <!-- joint name="${name}_arm_hand_fixed_joint" type="fixed">
      <origin xyz="${-1 * 0.075} -0.075 -0.094"
              rpy="${0.5*1*M_PI} 0 ${(1.5 + 0.25*1)*M_PI}"/>
      <parent link="${name}_arm_7_link"/>
      <child link="${name}_arm_hand_link"/>
    </joint>

    <link name="${name}_arm_hand_link" / -->
  </macro>

</robot>
